Traceback (most recent call last):
  File "/home/runner/micromamba/envs/coastal/lib/python3.11/site-packages/jupyter_cache/executors/utils.py", line 58, in single_nb_execution
    executenb(
  File "/home/runner/micromamba/envs/coastal/lib/python3.11/site-packages/nbclient/client.py", line 1305, in execute
    return NotebookClient(nb=nb, resources=resources, km=km, **kwargs).execute()
           ^^^^^^^^^^^^^^^^^^^^^^^^^^^^^^^^^^^^^^^^^^^^^^^^^^^^^^^^^^^^^^^^^^^^^
  File "/home/runner/micromamba/envs/coastal/lib/python3.11/site-packages/jupyter_core/utils/__init__.py", line 165, in wrapped
    return loop.run_until_complete(inner)
           ^^^^^^^^^^^^^^^^^^^^^^^^^^^^^^
  File "/home/runner/micromamba/envs/coastal/lib/python3.11/asyncio/base_events.py", line 654, in run_until_complete
    return future.result()
           ^^^^^^^^^^^^^^^
  File "/home/runner/micromamba/envs/coastal/lib/python3.11/site-packages/nbclient/client.py", line 705, in async_execute
    await self.async_execute_cell(
  File "/home/runner/micromamba/envs/coastal/lib/python3.11/site-packages/nbclient/client.py", line 1058, in async_execute_cell
    await self._check_raise_for_error(cell, cell_index, exec_reply)
  File "/home/runner/micromamba/envs/coastal/lib/python3.11/site-packages/nbclient/client.py", line 914, in _check_raise_for_error
    raise CellExecutionError.from_cell_and_msg(cell, exec_reply_content)
nbclient.exceptions.CellExecutionError: An error occurred while executing the following cell:
------------------
import pathlib
from pathlib import Path
import sys
import warnings
import ipywidgets as widgets
from ipywidgets import interact
from matplotlib.patches import Patch
from matplotlib.ticker import MaxNLocator, StrMethodFormatter
import matplotlib.pyplot as plt
import matplotlib.dates as mdates
import numpy as np
import pandas as pd
import cartopy.crs as ccrs
import xarray as xr
from datetime import datetime, timedelta
from IPython.display import display, Image
import math
import pandas as pd
import pooch
import pickle
from scipy import stats
with warnings.catch_warnings():
    warnings.simplefilter("ignore", category=RuntimeWarning)
    import utide

cwd = pathlib.Path().resolve()
proj_dir = cwd.parent.parent.parent  # this is the root of the CoastalCodeBook
sys.path.append(str(proj_dir))

from initialize.Tide_Initialize import plot_2timeseries_with_interactive_controls, questions_4b
------------------


[0;31m---------------------------------------------------------------------------[0m
[0;31mModuleNotFoundError[0m                       Traceback (most recent call last)
Cell [0;32mIn[1], line 24[0m
[1;32m     22[0m [38;5;28;01mwith[39;00m warnings[38;5;241m.[39mcatch_warnings():
[1;32m     23[0m     warnings[38;5;241m.[39msimplefilter([38;5;124m"[39m[38;5;124mignore[39m[38;5;124m"[39m, category[38;5;241m=[39m[38;5;167;01mRuntimeWarning[39;00m)
[0;32m---> 24[0m     [38;5;28;01mimport[39;00m [38;5;21;01mutide[39;00m
[1;32m     26[0m cwd [38;5;241m=[39m pathlib[38;5;241m.[39mPath()[38;5;241m.[39mresolve()
[1;32m     27[0m proj_dir [38;5;241m=[39m cwd[38;5;241m.[39mparent[38;5;241m.[39mparent[38;5;241m.[39mparent  [38;5;66;03m# this is the root of the CoastalCodeBook[39;00m

[0;31mModuleNotFoundError[0m: No module named 'utide'

